Workbook
Name AcceptableRisk: '2. Enterprise Parameters'!$E$35
Name AcceptableRisk1: 'Enterprise Parameters -EXAMPLE'!$E$35
Name Asset_Classes: Table10[[#Data],[Asset Classes]]
Name Industry: tblVCDBIndex[Asset Class]
Name Industry: tblVCDBIndex[Asset Class]
Name Industry: tblVCDBIndex[Asset Class]
Name Industry: tblVCDBIndex[Asset Class]
Name Industry: tblVCDBIndex[Asset Class]
Name Maturity_Score: tblMaturityScores[Maturity Scores]
Name Maturity_Score: tblMaturityScores[Maturity Scores]
Name Maturity_Score: tblMaturityScores[Maturity Scores]
Name Maturity_Score: tblMaturityScores[Maturity Scores]
Name Maturity_Score: tblMaturityScores[Maturity Scores]

Sheet Cover

Sheet MIS 595
C6: This workbook has been edited to work with the MIS 595 class. Several columns in the Risk Register were removed to simplify matters.

Sheet 1. Impact Criteria Survey 
D2: Prompt | E2: Response
B3: 1 | C3: Mission | D3: How would you concisely describe the benefit that your enterprise provides your customers, clients, constituents, or the public? This is why they engage in this risk with you. | E3: Fabella Bank exists to provide secure, reliable, and accessible financial services to customers in the Springfield area. Its mission is to protect customer funds, support financial growth, and maintain trust through safe and modern banking technology.
C5: Instructions: Imagine that your enterprise suffers a cybersecurity or information security incident. Describe in the spaces provided below how you would determine that the impacts to your mission were acceptable, or unacceptable.
C7: Impact Magnitude | D7: Prompt | E7: Response
C8: Negligible | D8: What observable evidence would you have that your mission - as you defined it above - would be unaffected? | E8: A small disruption occurs but does not affect customers or the bank’s ability to serve them.
C9: Acceptable | D9: What observable evidence would you have that your mission would be compromised, but it would not require correction? | E9: The bank can still achieve its mission with little or no impact on customer trust
C10: Unacceptable | D10: What observable evidence would you have that your mission would be compromised in a way that would require correction, but the correction could be achieved through the normal course of business? | E10: The bank must reinvest time or money to fix the situation before it can continue serving customers reliably
C11: High | D11: What observable evidence would you have that your mission would be compromised so badly that extraordinary efforts would be required to restore it? | E11: The bank’s ability to provide services is significantly affected for an extended time.
C12: Catastrophic | D12: What observable evidence would you have that your mission would be compromised so badly that it could not be achieved? | E12: The bank cannot achieve its mission, and customer trust is severely damaged.
D15: Prompt | E15: Response
B16: 2 | C16: Operational Objectives | D16: What business or organizational goals does the enterprise attempt to achieve? | E16: • Keep banking systems like MYBANK, ERP, ATMs, and mobile apps running smoothly. • Protect customer and employee information from unauthorized access. • Ensure daily operations such as deposits, withdrawals, loan processing, payroll, and reporting run without disruption. • Maintain compliance with financial and cybersecurity regulations.
C18: Instructions: Imagine that your enterprise suffers a cybersecurity or information security incident. Describe in the spaces provided below how you would determine that the impacts to your operational objectives were acceptable, or unacceptable.
C20: Impact Magnitude | D20: Prompt | E20: Response
C21: Negligible | D21: What observable evidence would you have that your operational objectives - as you defined them above - would be unaffected? | E21: Routine work may slow down briefly but returns to normal without extra effort.
C22: Acceptable | D22: What observable evidence would you have that your operational objectives would be compromised, but it would not require correction? | E22: Minor issues may require small adjustments but no major cost or downtime
C23: Unacceptable | D23: What observable evidence would you have that your operational objectives would be compromised in a way that would require correction, but the correction could be achieved through the normal course of business? | E23: Operations are disrupted enough that extra resources or overtime work are needed to catch up.
C24: High | D24: What observable evidence would you have that your operational objectives would be compromised so badly that extraordinary efforts would be required to restore them? | E24: Key systems become unavailable, causing major downtime, financial loss, or regulatory concerns.
C25: Catastrophic | D25: What observable evidence would you have that your operational objectives would be compromised so badly that they could not be achieved? | E25: Critical systems fail completely, operations stop, and recovery requires full restoration efforts
D28: Prompt | E28: Response
B29: 3 | C29: Financial Objectives | D29: What are the unexpected cost outlays that your enterprise could or could not tolerate? | E29: Not Applicable for MIS 595 Course
C31: Instructions: Imagine that your enterprise suffers a cybersecurity or information security incident. Describe in the spaces provided below how you would determine that the impacts to your financial objectives were acceptable, or unacceptable.
C33: Impact Magnitude | D33: Prompt | E33: Response
C34: Negligible | D34: What observable evidence would you have that your financial objectives - as you defined them above - would be unaffected? | E34: Not Applicable for MIS 595 Course
C35: Acceptable | D35: What observable evidence would you have that your financial objectives would be compromised, but it would not require correction? | E35: Not Applicable for MIS 595 Course
C36: Unacceptable | D36: What observable evidence would you have that your financial objectives would be compromised in a way that would require correction, but the correction could be achieved through the normal course of business? | E36: Not Applicable for MIS 595 Course
C37: High | D37: What observable evidence would you have that your financial objectives would be compromised so badly that extraordinary efforts would be required to restore them? | E37: Not Applicable for MIS 595 Course
C38: Catastrophic | D38: Leave this blank
D41: Prompt | E41: Response
B42: 4 | C42: Obligations | D42: What harm may foreseeably come to others as a result of a cybersecurity incident? | E42: • Protect customer data (PII, account details, transactions). • Ensure fair and uninterrupted access to financial services. • Report breaches or outages to regulators when required. • Prevent harm to customers, employees, and third-party partners
C44: Instructions: Imagine that your enterprise suffers a cybersecurity or information security incident. Describe in the spaces provided below how you would determine that the impacts to your obligations (harm, to others) were acceptable, or unacceptable.
C46: Impact Magnitude | D46: Prompt | E46: Response
C47: Negligible | D47: Describe a condition where others would not be harmed. | E47: No harm to customers or partners; no regulatory action required.
C48: Acceptable | D48: Describe a condition where others would not be harmed to a degree that required correction or compensation. | E48: No harm to customers, and any inconvenience is easily corrected.
C49: Unacceptable | D49: Describe a condition where one or few others would be harmed to a degree that you could correct. | E49: Customers or partners may experience temporary harm or delayed services, but the harm is fixable.
C50: High | D50: Describe a condition where many others would be harmed to a degree that you could correct, or where few others are harmed to a degree that others would always have a small degree of impairment. | E50: Customers may face real impacts such as delayed transactions, financial stress, or other risks.
C51: Catastrophic | D51: Describe a condition where others would be irreparably harmed. | E51: Harm to customers or partners is long-lasting or not fully correctable; regulators may intervene.

Sheet 2. Enterprise Parameters
B2: 1 | C2: Enterprise Risk Assessment Criteria | D2: Enterprise Name | E2: BANK NAME
D3: Scope | E3: ALL BRANCHES
D4: Last Completed (Date) | E4: 45053
B8: 2 | C8: Impact Criteria
C10: Impact Scores | D10: Mission | E10: Operational Objectives | F10: Financial Objectives | G10: Obligations
C11: Definition | D11: Fabella Bank exists to provide secure, reliable, and accessible financial services to customers in the Springfield area. Its mission is to protect customer funds, support financial growth, and maintain trust through safe and modern banking technology | E11: =IF(ISBLANK('1. Impact Criteria Survey '!E16),"",'1. Impact Criteria Survey '!E16) -> • Keep banking systems like MYBANK, ERP, ATMs, and mobile apps running smoothly. • Protect customer and employee information from unauthorized access. • Ensure daily operations such as deposits, withdrawals, loan processing, payroll, and reporting run without disruption. • Maintain compliance with financial and cybersecurity regulations. | F11: =IF(ISBLANK('1. Impact Criteria Survey '!E29),"",'1. Impact Criteria Survey '!E29) -> Not Applicable for MIS 595 Course | G11: =IF(ISBLANK('1. Impact Criteria Survey '!E42),"",'1. Impact Criteria Survey '!E42) -> • Protect customer data (PII, account details, transactions). • Ensure fair and uninterrupted access to financial services. • Report breaches or outages to regulators when required. • Prevent harm to customers, employees, and third-party partners
C12: 1. Negligible | D12: =IF(ISBLANK('1. Impact Criteria Survey '!E8),"",'1. Impact Criteria Survey '!E8) -> A small disruption occurs but does not affect customers or the bank’s ability to serve them. | E12: =IF(ISBLANK('1. Impact Criteria Survey '!E21),"",'1. Impact Criteria Survey '!E21) -> Routine work may slow down briefly but returns to normal without extra effort. | F12: =IF(ISBLANK('1. Impact Criteria Survey '!E34),"",'1. Impact Criteria Survey '!E34) -> Not Applicable for MIS 595 Course | G12: =IF(ISBLANK('1. Impact Criteria Survey '!E47),"",'1. Impact Criteria Survey '!E47) -> No harm to customers or partners; no regulatory action required.
C13: 2. Acceptable | D13: =IF(ISBLANK('1. Impact Criteria Survey '!E9),"",'1. Impact Criteria Survey '!E9) -> The bank can still achieve its mission with little or no impact on customer trust | E13: =IF(ISBLANK('1. Impact Criteria Survey '!E22),"",'1. Impact Criteria Survey '!E22) -> Minor issues may require small adjustments but no major cost or downtime | F13: =IF(ISBLANK('1. Impact Criteria Survey '!E35),"",'1. Impact Criteria Survey '!E35) -> Not Applicable for MIS 595 Course | G13: =IF(ISBLANK('1. Impact Criteria Survey '!E48),"",'1. Impact Criteria Survey '!E48) -> No harm to customers, and any inconvenience is easily corrected.
C14: 3. Unacceptable | D14: =IF(ISBLANK('1. Impact Criteria Survey '!E10),"",'1. Impact Criteria Survey '!E10) -> The bank must reinvest time or money to fix the situation before it can continue serving customers reliably | E14: =IF(ISBLANK('1. Impact Criteria Survey '!E23),"",'1. Impact Criteria Survey '!E23) -> Operations are disrupted enough that extra resources or overtime work are needed to catch up. | F14: =IF(ISBLANK('1. Impact Criteria Survey '!E36),"",'1. Impact Criteria Survey '!E36) -> Not Applicable for MIS 595 Course | G14: =IF(ISBLANK('1. Impact Criteria Survey '!E49),"",'1. Impact Criteria Survey '!E49) -> Customers or partners may experience temporary harm or delayed services, but the harm is fixable.
C15: 4. High | D15: =IF(ISBLANK('1. Impact Criteria Survey '!E11),"",'1. Impact Criteria Survey '!E11) -> The bank’s ability to provide services is significantly affected for an extended time. | E15: =IF(ISBLANK('1. Impact Criteria Survey '!E24),"",'1. Impact Criteria Survey '!E24) -> Key systems become unavailable, causing major downtime, financial loss, or regulatory concerns. | F15: =IF(ISBLANK('1. Impact Criteria Survey '!E37),"",'1. Impact Criteria Survey '!E37) -> Not Applicable for MIS 595 Course | G15: =IF(ISBLANK('1. Impact Criteria Survey '!E50),"",'1. Impact Criteria Survey '!E50) -> Customers may face real impacts such as delayed transactions, financial stress, or other risks.
C16: 5. Catastrophic | D16: =IF(ISBLANK('1. Impact Criteria Survey '!E12),"",'1. Impact Criteria Survey '!E12) -> The bank cannot achieve its mission, and customer trust is severely damaged. | E16: =IF(ISBLANK('1. Impact Criteria Survey '!E25),"",'1. Impact Criteria Survey '!E25) -> Critical systems fail completely, operations stop, and recovery requires full restoration efforts | F16: =IF(ISBLANK('1. Impact Criteria Survey '!E38),"",'1. Impact Criteria Survey '!E38) | G16: =IF(ISBLANK('1. Impact Criteria Survey '!E51),"",'1. Impact Criteria Survey '!E51) -> Harm to customers or partners is long-lasting or not fully correctable; regulators may intervene.
B20: 3 | C20: Expectancy Criteria
C22: Expectancy Score | D22: Expectancy | E22: Criteria
C23: 1 | D23: Remote | E23: Safeguard would reliably prevent the threat.
C24: 2 | D24: Unlikely | E24: Safeguard would reliably prevent most occurrences of the threat.
C25: 3 | D25: As likely as not | E25: Safeguard would prevent as many threat occurrences as it would miss.
C26: 4 | D26: Likely | E26: Safeguard would prevent few threat occurrences.
C27: 5 | D27: Certain | E27: Safeguard would not prevent threat occurrences.
B31: 4 | C31: Risk Acceptance Criteria
C33: We would start to invest against risks to prevent this expectancy and impact, or higher. | D33: Expectancy | E33: Impact
D34: 3 | E34: 3
D35: Acceptable Risk is less than … | E35: =D34*E34 -> 9
B39: 5 | C39: Inherent Risk Criteria | D39: What is the highest impact to the Mission, Operational Objectives, Financial Objectives, and Obligations that each Asset Type could cause? The "Enterprise" Asset Class will automatically use the highest Impact Score you provide for the assets below.
C41: Asset Class | D41: Mission Impact | E41: Operational Objectives Impact | F41: Financial Objectives Impact | G41: Obligations Impact
C42: Enterprise | D42: =IF(MAX(D43:D47)=0,"",MAX(D43:D47)) -> 5 | E42: =IF(MAX(E43:E47)=0,"",MAX(E43:E47)) -> 5 | F42: 1 | G42: =IF(MAX(G43:G47)=0,"",MAX(G43:G47)) -> 5
C43: Devices | D43: 3 | E43: 3 | F43: 1 | G43: 3
C44: Applications | D44: 3 | E44: 4 | F44: 1 | G44: 4
C45: Data | D45: 4 | E45: 4 | F45: 1 | G45: 4
C46: Network | D46: 4 | E46: 5 | F46: 1 | G46: 5
C47: Users | D47: 5 | E47: 5 | F47: 1 | G47: 5

Sheet 3b. Risk Register Controls v8
B2: Enterprise Risk Assessment Criteria | D2: Enterprise Name | E2: FABELLA BANK
D3: Scope | E3: =IF(ISBLANK('2. Enterprise Parameters'!E3),"",'2. Enterprise Parameters'!E3) -> ALL BRANCHES
D4: Last Completed (Date) | E4: Wednesday, December 10, 2025
B8: Risk Register | D8: Risk Analysis | U8: Risk Register | V8: Risk Treatment | AM8: Reasonable Annual Cost
B9: For MIS 595 - we will only focus on a handful of the controls - filtered with column C
B10: Asset Class | C10: MIS 595 Focused Controls | D10: CIS Safeguard #2 | E10: CIS Safeguard Title | F10: Our Implementation | G10: Vulnerabilities | H10: Safeguard Maturity Score | I10: VCDB Index | J10: Expectancy Score | K10: Impact to Mission | L10: Impact to Operational Objectives | M10: Impact to Financial Objectives | N10: Impact to Obligations | O10: Risk Score | P10: Risk Level | Q10: Risk Treatment Option | R10: Risk Treatment Safeguard | S10: Risk Treatment Safeguard Title | T10: Risk Treatment Safeguard Description | U10: Our Planned Implementation | V10: Risk Treatment Safeguard Maturity Score | W10: Risk Treatment Safeguard Expectancy Score | X10: Risk Treatment Safeguard Impact to Mission | Y10: Risk Treatment Safeguard Impact to Operational Objectives | Z10: Risk Treatment Safeguard Impact to Financial Objectives | AA10: Risk Treatment Safeguard Impact to Obligations | AB10: Risk Treatment Safeguard Risk Score | AC10: Reasonable and Acceptable | AD10: Risk Treatment Safeguard Cost | AE10: Implementation Quarter | AF10: Implementation Year | AH10: Impact to Financial Objectives | AI10: Year | AJ10: Reasonable?
B11: Devices | C11: MIS 595 Focus | D11: 1.1 | E11: Establish and Maintain Detailed Enterprise Asset Inventory | F11: We maintain a centralized asset inventory using automated discovery tools to track all devices across Fabella Bank. | G11: No Vulnerability | H11: 5 | I11: =IFERROR(VLOOKUP(tblRiskRegister32[[#This Row],[Asset Class]],tblVCDBIndex[],4,FALSE),"") -> 1 | J11: =IFERROR(VLOOKUP(10*tblRiskRegister32[[#This Row],[Safeguard Maturity Score]]+tblRiskRegister32[[#This Row],[VCDB Index]],tblHITIndexWeightTable[],4,FALSE),"") -> 1 | K11: =VLOOKUP(tblRiskRegister32[[#This Row],[Asset Class]],tblInherentImpacts30[],2,FALSE) -> 3 | L11: =VLOOKUP(tblRiskRegister32[[#This Row],[Asset Class]],tblInherentImpacts30[],3,FALSE) -> 3 | M11: =VLOOKUP(tblRiskRegister32[[#This Row],[Asset Class]],tblInherentImpacts30[],4,FALSE) -> 1 | N11: =VLOOKUP(tblRiskRegister32[[#This Row],[Asset Class]],tblInherentImpacts30[],5,FALSE) -> 3 | O11: =IFERROR(MAX(tblRiskRegister32[[#This Row],[Impact to Mission]:[Impact to Obligations]])*tblRiskRegister32[[#This Row],[Expectancy Score]],"") -> 3 | P11: =tblRiskRegister32[[#This Row],[Risk Score]] -> 3 | Q11: Accept | R11: 1.1 | S11: Establish and Maintain Detailed Enterprise Asset Inventory | T11: Establish and maintain an accurate, detailed, and up-to-date inventory of all enterprise assets with the potential to store or process data, to include: end-user devices (including portable and mobile), network devices, non-computing/IoT devices, and servers. Ensure the inventory records the network address (if static), hardware address, machine name, enterprise asset owner, department for each asset, and whether the asset has been approved to connect to the network. For mobile end-user devices, MDM type tools can support this process, where appropriate. This inventory includes assets connected to the infrastructure physically, virtually, remotely, and those within cloud environments. Additionally, it includes assets that are regularly connected to the enterprise’s network infrastructure, even if they are not under control of the enterprise. Review and update the inventory of all enterprise assets bi-annually, or more frequently. | W11: =IFERROR(VLOOKUP(10*tblRiskRegister32[[#This Row],[Risk Treatment Safeguard Maturity Score]]+tblRiskRegister32[[#This Row],[VCDB Index]],tblHITIndexWeightTable[],4,FALSE),"") | X11: =VLOOKUP(tblRiskRegister32[[#This Row],[Asset Class]],tblInherentImpacts30[],2,FALSE) -> 3 | Y11: =VLOOKUP(tblRiskRegister32[[#This Row],[Asset Class]],tblInherentImpacts30[],3,FALSE) -> 3 | Z11: =VLOOKUP(tblRiskRegister32[[#This Row],[Asset Class]],tblInherentImpacts30[],3,FALSE) -> 3 | AA11: =VLOOKUP(tblRiskRegister32[[#This Row],[Asset Class]],tblInherentImpacts30[],4,FALSE) -> 1 | AB11: =IFERROR(MAX(tblRiskRegister32[[#This Row],[Risk Treatment Safeguard Impact to Mission]:[Risk Treatment Safeguard Impact to Obligations]])*tblRiskRegister32[[#This Row],[Risk Treatment Safeguard Expectancy Score]],"") | AC11: =IF(tblRiskRegister32[[#This Row],[Risk Score]]>AcceptableRisk,IF(tblRiskRegister32[[#This Row],[Risk Treatment Safeguard Risk Score]]<AcceptableRisk, IF(tblRiskRegister32[[#This Row],[Risk Treatment Safeguard Risk Score]]<=tblRiskRegister32[[#This Row],[Risk Score]],"Yes","No"),"No"),"Yes") -> Yes | AH11: =SUMIF(tblRiskRegister32[[#All],[Implementation Year]],"="&tblCostImpacts33[[#This Row],[Year]],tblRiskRegister32[[#All],[Risk Treatment Safeguard Cost]]) -> 0 | AI11: 2021 | AJ11: =IF(tblCostImpacts33[[#This Row],[Impact to Financial Objectives]]<='2. Enterprise Parameters'!$F$13,"Yes","No") -> Yes
B12: Devices | D12: 1.2 | E12: Address Unauthorized Assets | I12: =IFERROR(VLOOKUP(tblRiskRegister32[[#This Row],[Asset Class]],tblVCDBIndex[],4,FALSE),"") -> 1 | J12: =IFERROR(VLOOKUP(10*tblRiskRegister32[[#This Row],[Safeguard Maturity Score]]+tblRiskRegister32[[#This Row],[VCDB Index]],tblHITIndexWeightTable[],4,FALSE),"") | K12: =VLOOKUP(tblRiskRegister32[[#This Row],[Asset Class]],tblInherentImpacts30[],2,FALSE) -> 3 | L12: =VLOOKUP(tblRiskRegister32[[#This Row],[Asset Class]],tblInherentImpacts30[],3,FALSE) -> 3 | M12: =VLOOKUP(tblRiskRegister32[[#This Row],[Asset Class]],tblInherentImpacts30[],4,FALSE) -> 1 | N12: =VLOOKUP(tblRiskRegister32[[#This Row],[Asset Class]],tblInherentImpacts30[],5,FALSE) -> 3 | O12: =IFERROR(MAX(tblRiskRegister32[[#This Row],[Impact to Mission]:[Impact to Obligations]])*tblRiskRegister32[[#This Row],[Expectancy Score]],"") | P12: =tblRiskRegister32[[#This Row],[Risk Score]] | R12: 1.2 | S12: Address Unauthorized Assets | T12: Ensure that a process exists to address unauthorized assets on a weekly basis. The enterprise may choose to remove the asset from the network, deny the asset from connecting remotely to the network, or quarantine the asset. | W12: =IFERROR(VLOOKUP(10*tblRiskRegister32[[#This Row],[Risk Treatment Safeguard Maturity Score]]+tblRiskRegister32[[#This Row],[VCDB Index]],tblHITIndexWeightTable[],4,FALSE),"") | X12: =VLOOKUP(tblRiskRegister32[[#This Row],[Asset Class]],tblInherentImpacts30[],2,FALSE) -> 3 | Y12: =VLOOKUP(tblRiskRegister32[[#This Row],[Asset Class]],tblInherentImpacts30[],3,FALSE) -> 3 | Z12: =VLOOKUP(tblRiskRegister32[[#This Row],[Asset Class]],tblInherentImpacts30[],3,FALSE) -> 3 | AA12: =VLOOKUP(tblRiskRegister32[[#This Row],[Asset Class]],tblInherentImpacts30[],4,FALSE) -> 1 | AB12: =IFERROR(MAX(tblRiskRegister32[[#This Row],[Risk Treatment Safeguard Impact to Mission]:[Risk Treatment Safeguard Impact to Obligations]])*tblRiskRegister32[[#This Row],[Risk Treatment Safeguard Expectancy Score]],"") | AC12: =IF(tblRiskRegister32[[#This Row],[Risk Score]]>AcceptableRisk,IF(tblRiskRegister32[[#This Row],[Risk Treatment Safeguard Risk Score]]<AcceptableRisk, IF(tblRiskRegister32[[#This Row],[Risk Treatment Safeguard Risk Score]]<=tblRiskRegister32[[#This Row],[Risk Score]],"Yes","No"),"No"),"Yes") -> No | AH12: =SUMIF(tblRiskRegister32[[#All],[Implementation Year]],"="&tblCostImpacts33[[#This Row],[Year]],tblRiskRegister32[[#All],[Risk Treatment Safeguard Cost]]) -> 0 | AI12: 2022 | AJ12: =IF(tblCostImpacts33[[#This Row],[Impact to Financial Objectives]]<='2. Enterprise Parameters'!$F$13,"Yes","No") -> Yes
B13: Devices | D13: 1.3 | E13: Utilize an Active Discovery Tool | I13: =IFERROR(VLOOKUP(tblRiskRegister32[[#This Row],[Asset Class]],tblVCDBIndex[],4,FALSE),"") -> 1 | J13: =IFERROR(VLOOKUP(10*tblRiskRegister32[[#This Row],[Safeguard Maturity Score]]+tblRiskRegister32[[#This Row],[VCDB Index]],tblHITIndexWeightTable[],4,FALSE),"") | K13: =VLOOKUP(tblRiskRegister32[[#This Row],[Asset Class]],tblInherentImpacts30[],2,FALSE) -> 3 | L13: =VLOOKUP(tblRiskRegister32[[#This Row],[Asset Class]],tblInherentImpacts30[],3,FALSE) -> 3 | M13: =VLOOKUP(tblRiskRegister32[[#This Row],[Asset Class]],tblInherentImpacts30[],4,FALSE) -> 1 | N13: =VLOOKUP(tblRiskRegister32[[#This Row],[Asset Class]],tblInherentImpacts30[],5,FALSE) -> 3 | O13: =IFERROR(MAX(tblRiskRegister32[[#This Row],[Impact to Mission]:[Impact to Obligations]])*tblRiskRegister32[[#This Row],[Expectancy Score]],"") | P13: =tblRiskRegister32[[#This Row],[Risk Score]] | R13: 1.3 | S13: Utilize an Active Discovery Tool | T13: Utilize an active discovery tool to identify assets connected to the enterprise’s network. Configure the active discovery tool to execute daily, or more frequently. | W13: =IFERROR(VLOOKUP(10*tblRiskRegister32[[#This Row],[Risk Treatment Safeguard Maturity Score]]+tblRiskRegister32[[#This Row],[VCDB Index]],tblHITIndexWeightTable[],4,FALSE),"") | X13: =VLOOKUP(tblRiskRegister32[[#This Row],[Asset Class]],tblInherentImpacts30[],2,FALSE) -> 3 | Y13: =VLOOKUP(tblRiskRegister32[[#This Row],[Asset Class]],tblInherentImpacts30[],3,FALSE) -> 3 | Z13: =VLOOKUP(tblRiskRegister32[[#This Row],[Asset Class]],tblInherentImpacts30[],3,FALSE) -> 3 | AA13: =VLOOKUP(tblRiskRegister32[[#This Row],[Asset Class]],tblInherentImpacts30[],4,FALSE) -> 1 | AB13: =IFERROR(MAX(tblRiskRegister32[[#This Row],[Risk Treatment Safeguard Impact to Mission]:[Risk Treatment Safeguard Impact to Obligations]])*tblRiskRegister32[[#This Row],[Risk Treatment Safeguard Expectancy Score]],"") | AC13: =IF(tblRiskRegister32[[#This Row],[Risk Score]]>AcceptableRisk,IF(tblRiskRegister32[[#This Row],[Risk Treatment Safeguard Risk Score]]<AcceptableRisk, IF(tblRiskRegister32[[#This Row],[Risk Treatment Safeguard Risk Score]]<=tblRiskRegister32[[#This Row],[Risk Score]],"Yes","No"),"No"),"Yes") -> No | AH13: =SUMIF(tblRiskRegister32[[#All],[Implementation Year]],"="&tblCostImpacts33[[#This Row],[Year]],tblRiskRegister32[[#All],[Risk Treatment Safeguard Cost]]) -> 0 | AI13: 2023 | AJ13: =IF(tblCostImpacts33[[#This Row],[Impact to Financial Objectives]]<='2. Enterprise Parameters'!$F$13,"Yes","No") -> Yes
B14: Devices | D14: 1.4 | E14: Use Dynamic Host Configuration Protocol (DHCP) Logging to Update Enterprise Asset Inventory | I14: =IFERROR(VLOOKUP(tblRiskRegister32[[#This Row],[Asset Class]],tblVCDBIndex[],4,FALSE),"") -> 1 | J14: =IFERROR(VLOOKUP(10*tblRiskRegister32[[#This Row],[Safeguard Maturity Score]]+tblRiskRegister32[[#This Row],[VCDB Index]],tblHITIndexWeightTable[],4,FALSE),"") | K14: =VLOOKUP(tblRiskRegister32[[#This Row],[Asset Class]],tblInherentImpacts30[],2,FALSE) -> 3 | L14: =VLOOKUP(tblRiskRegister32[[#This Row],[Asset Class]],tblInherentImpacts30[],3,FALSE) -> 3 | M14: =VLOOKUP(tblRiskRegister32[[#This Row],[Asset Class]],tblInherentImpacts30[],4,FALSE) -> 1 | N14: =VLOOKUP(tblRiskRegister32[[#This Row],[Asset Class]],tblInherentImpacts30[],5,FALSE) -> 3 | O14: =IFERROR(MAX(tblRiskRegister32[[#This Row],[Impact to Mission]:[Impact to Obligations]])*tblRiskRegister32[[#This Row],[Expectancy Score]],"") | P14: =tblRiskRegister32[[#This Row],[Risk Score]] | R14: 1.4 | S14: Use Dynamic Host Configuration Protocol (DHCP) Logging to Update Enterprise Asset Inventory | T14: Use DHCP logging on all DHCP servers or Internet Protocol (IP) address management tools to update the enterprise’s asset inventory. Review and use logs to update the enterprise’s asset inventory weekly, or more frequently. | W14: =IFERROR(VLOOKUP(10*tblRiskRegister32[[#This Row],[Risk Treatment Safeguard Maturity Score]]+tblRiskRegister32[[#This Row],[VCDB Index]],tblHITIndexWeightTable[],4,FALSE),"") | X14: =VLOOKUP(tblRiskRegister32[[#This Row],[Asset Class]],tblInherentImpacts30[],2,FALSE) -> 3 | Y14: =VLOOKUP(tblRiskRegister32[[#This Row],[Asset Class]],tblInherentImpacts30[],3,FALSE) -> 3 | Z14: =VLOOKUP(tblRiskRegister32[[#This Row],[Asset Class]],tblInherentImpacts30[],3,FALSE) -> 3 | AA14: =VLOOKUP(tblRiskRegister32[[#This Row],[Asset Class]],tblInherentImpacts30[],4,FALSE) -> 1 | AB14: =IFERROR(MAX(tblRiskRegister32[[#This Row],[Risk Treatment Safeguard Impact to Mission]:[Risk Treatment Safeguard Impact to Obligations]])*tblRiskRegister32[[#This Row],[Risk Treatment Safeguard Expectancy Score]],"") | AC14: =IF(tblRiskRegister32[[#This Row],[Risk Score]]>AcceptableRisk,IF(tblRiskRegister32[[#This Row],[Risk Treatment Safeguard Risk Score]]<AcceptableRisk, IF(tblRiskRegister32[[#This Row],[Risk Treatment Safeguard Risk Score]]<=tblRiskRegister32[[#This Row],[Risk Score]],"Yes","No"),"No"),"Yes") -> No | AH14: =SUMIF(tblRiskRegister32[[#All],[Implementation Year]],"="&tblCostImpacts33[[#This Row],[Year]],tblRiskRegister32[[#All],[Risk Treatment Safeguard Cost]]) -> 0 | AI14: 2024 | AJ14: =IF(tblCostImpacts33[[#This Row],[Impact to Financial Objectives]]<='2. Enterprise Parameters'!$F$13,"Yes","No") -> Yes
B15: Applications | D15: 2.1 | E15: Establish and Maintain a Software Inventory | I15: =IFERROR(VLOOKUP(tblRiskRegister32[[#This Row],[Asset Class]],tblVCDBIndex[],4,FALSE),"") -> 2 | J15: =IFERROR(VLOOKUP(10*tblRiskRegister32[[#This Row],[Safeguard Maturity Score]]+tblRiskRegister32[[#This Row],[VCDB Index]],tblHITIndexWeightTable[],4,FALSE),"") | K15: =VLOOKUP(tblRiskRegister32[[#This Row],[Asset Class]],tblInherentImpacts30[],2,FALSE) -> 3 | L15: =VLOOKUP(tblRiskRegister32[[#This Row],[Asset Class]],tblInherentImpacts30[],3,FALSE) -> 4 | M15: =VLOOKUP(tblRiskRegister32[[#This Row],[Asset Class]],tblInherentImpacts30[],4,FALSE) -> 1 | N15: =VLOOKUP(tblRiskRegister32[[#This Row],[Asset Class]],tblInherentImpacts30[],5,FALSE) -> 4 | O15: =IFERROR(MAX(tblRiskRegister32[[#This Row],[Impact to Mission]:[Impact to Obligations]])*tblRiskRegister32[[#This Row],[Expectancy Score]],"") | P15: =tblRiskRegister32[[#This Row],[Risk Score]] | R15: 2.1 | S15: Establish and Maintain a Software Inventory | T15: Establish and maintain a detailed inventory of all licensed software installed on enterprise assets. The software inventory must document the title, publisher, initial install/use date, and business purpose for each entry; where appropriate, include the Uniform Resource Locator (URL), app store(s), version(s), deployment mechanism, and decommission date. Review and update the software inventory bi-annually, or more frequently. | W15: =IFERROR(VLOOKUP(10*tblRiskRegister32[[#This Row],[Risk Treatment Safeguard Maturity Score]]+tblRiskRegister32[[#This Row],[VCDB Index]],tblHITIndexWeightTable[],4,FALSE),"") | X15: =VLOOKUP(tblRiskRegister32[[#This Row],[Asset Class]],tblInherentImpacts30[],2,FALSE) -> 3 | Y15: =VLOOKUP(tblRiskRegister32[[#This Row],[Asset Class]],tblInherentImpacts30[],3,FALSE) -> 4 | Z15: =VLOOKUP(tblRiskRegister32[[#This Row],[Asset Class]],tblInherentImpacts30[],3,FALSE) -> 4 | AA15: =VLOOKUP(tblRiskRegister32[[#This Row],[Asset Class]],tblInherentImpacts30[],4,FALSE) -> 1 | AB15: =IFERROR(MAX(tblRiskRegister32[[#This Row],[Risk Treatment Safeguard Impact to Mission]:[Risk Treatment Safeguard Impact to Obligations]])*tblRiskRegister32[[#This Row],[Risk Treatment Safeguard Expectancy Score]],"") | AC15: =IF(tblRiskRegister32[[#This Row],[Risk Score]]>AcceptableRisk,IF(tblRiskRegister32[[#This Row],[Risk Treatment Safeguard Risk Score]]<AcceptableRisk, IF(tblRiskRegister32[[#This Row],[Risk Treatment Safeguard Risk Score]]<=tblRiskRegister32[[#This Row],[Risk Score]],"Yes","No"),"No"),"Yes") -> No | AH15: =SUMIF(tblRiskRegister32[[#All],[Implementation Year]],"="&tblCostImpacts33[[#This Row],[Year]],tblRiskRegister32[[#All],[Risk Treatment Safeguard Cost]]) -> 0 | AI15: 2025 | AJ15: =IF(tblCostImpacts33[[#This Row],[Impact to Financial Objectives]]<='2. Enterprise Parameters'!$F$13,"Yes","No") -> Yes
B16: Applications | D16: 2.2 | E16: Ensure Authorized Software is Currently Supported | I16: =IFERROR(VLOOKUP(tblRiskRegister32[[#This Row],[Asset Class]],tblVCDBIndex[],4,FALSE),"") -> 2 | J16: =IFERROR(VLOOKUP(10*tblRiskRegister32[[#This Row],[Safeguard Maturity Score]]+tblRiskRegister32[[#This Row],[VCDB Index]],tblHITIndexWeightTable[],4,FALSE),"") | K16: =VLOOKUP(tblRiskRegister32[[#This Row],[Asset Class]],tblInherentImpacts30[],2,FALSE) -> 3 | L16: =VLOOKUP(tblRiskRegister32[[#This Row],[Asset Class]],tblInherentImpacts30[],3,FALSE) -> 4 | M16: =VLOOKUP(tblRiskRegister32[[#This Row],[Asset Class]],tblInherentImpacts30[],4,FALSE) -> 1 | N16: =VLOOKUP(tblRiskRegister32[[#This Row],[Asset Class]],tblInherentImpacts30[],5,FALSE) -> 4 | O16: =IFERROR(MAX(tblRiskRegister32[[#This Row],[Impact to Mission]:[Impact to Obligations]])*tblRiskRegister32[[#This Row],[Expectancy Score]],"") | P16: =tblRiskRegister32[[#This Row],[Risk Score]] | R16: 2.2 | S16: Ensure Authorized Software is Currently Supported | T16: Ensure that only currently supported software is designated as authorized in the software inventory for enterprise assets. If software is unsupported, yet necessary for the fulfillment of the enterprise’s mission, document an exception detailing mitigating controls and residual risk acceptance. For any unsupported software without an exception documentation, designate as unauthorized. Review the software list to verify software support at least monthly, or more frequently. | W16: =IFERROR(VLOOKUP(10*tblRiskRegister32[[#This Row],[Risk Treatment Safeguard Maturity Score]]+tblRiskRegister32[[#This Row],[VCDB Index]],tblHITIndexWeightTable[],4,FALSE),"") | X16: =VLOOKUP(tblRiskRegister32[[#This Row],[Asset Class]],tblInherentImpacts30[],2,FALSE) -> 3 | Y16: =VLOOKUP(tblRiskRegister32[[#This Row],[Asset Class]],tblInherentImpacts30[],3,FALSE) -> 4 | Z16: =VLOOKUP(tblRiskRegister32[[#This Row],[Asset Class]],tblInherentImpacts30[],3,FALSE) -> 4 | AA16: =VLOOKUP(tblRiskRegister32[[#This Row],[Asset Class]],tblInherentImpacts30[],4,FALSE) -> 1 | AB16: =IFERROR(MAX(tblRiskRegister32[[#This Row],[Risk Treatment Safeguard Impact to Mission]:[Risk Treatment Safeguard Impact to Obligations]])*tblRiskRegister32[[#This Row],[Risk Treatment Safeguard Expectancy Score]],"") | AC16: =IF(tblRiskRegister32[[#This Row],[Risk Score]]>AcceptableRisk,IF(tblRiskRegister32[[#This Row],[Risk Treatment Safeguard Risk Score]]<AcceptableRisk, IF(tblRiskRegister32[[#This Row],[Risk Treatment Safeguard Risk Score]]<=tblRiskRegister32[[#This Row],[Risk Score]],"Yes","No"),"No"),"Yes") -> No | AH16: =SUMIF(tblRiskRegister32[[#All],[Implementation Year]],"="&tblCostImpacts33[[#This Row],[Year]],tblRiskRegister32[[#All],[Risk Treatment Safeguard Cost]]) -> 0 | AI16: 2026 | AJ16: =IF(tblCostImpacts33[[#This Row],[Impact to Financial Objectives]]<='2. Enterprise Parameters'!$F$13,"Yes","No") -> Yes
B17: Applications | D17: 2.3 | E17: Address Unauthorized Software | I17: =IFERROR(VLOOKUP(tblRiskRegister32[[#This Row],[Asset Class]],tblVCDBIndex[],4,FALSE),"") -> 2 | J17: =IFERROR(VLOOKUP(10*tblRiskRegister32[[#This Row],[Safeguard Maturity Score]]+tblRiskRegister32[[#This Row],[VCDB Index]],tblHITIndexWeightTable[],4,FALSE),"") | K17: =VLOOKUP(tblRiskRegister32[[#This Row],[Asset Class]],tblInherentImpacts30[],2,FALSE) -> 3 | L17: =VLOOKUP(tblRiskRegister32[[#This Row],[Asset Class]],tblInherentImpacts30[],3,FALSE) -> 4 | M17: =VLOOKUP(tblRiskRegister32[[#This Row],[Asset Class]],tblInherentImpacts30[],4,FALSE) -> 1 | N17: =VLOOKUP(tblRiskRegister32[[#This Row],[Asset Class]],tblInherentImpacts30[],5,FALSE) -> 4 | O17: =IFERROR(MAX(tblRiskRegister32[[#This Row],[Impact to Mission]:[Impact to Obligations]])*tblRiskRegister32[[#This Row],[Expectancy Score]],"") | P17: =tblRiskRegister32[[#This Row],[Risk Score]] | R17: 2.3 | S17: Address Unauthorized Software | T17: Ensure that unauthorized software is either removed from use on enterprise assets or receives a documented exception. Review monthly, or more frequently. | W17: =IFERROR(VLOOKUP(10*tblRiskRegister32[[#This Row],[Risk Treatment Safeguard Maturity Score]]+tblRiskRegister32[[#This Row],[VCDB Index]],tblHITIndexWeightTable[],4,FALSE),"") | X17: =VLOOKUP(tblRiskRegister32[[#This Row],[Asset Class]],tblInherentImpacts30[],2,FALSE) -> 3 | Y17: =VLOOKUP(tblRiskRegister32[[#This Row],[Asset Class]],tblInherentImpacts30[],3,FALSE) -> 4 | Z17: =VLOOKUP(tblRiskRegister32[[#This Row],[Asset Class]],tblInherentImpacts30[],3,FALSE) -> 4 | AA17: =VLOOKUP(tblRiskRegister32[[#This Row],[Asset Class]],tblInherentImpacts30[],4,FALSE) -> 1 | AB17: =IFERROR(MAX(tblRiskRegister32[[#This Row],[Risk Treatment Safeguard Impact to Mission]:[Risk Treatment Safeguard Impact to Obligations]])*tblRiskRegister32[[#This Row],[Risk Treatment Safeguard Expectancy Score]],"") | AC17: =IF(tblRiskRegister32[[#This Row],[Risk Score]]>AcceptableRisk,IF(tblRiskRegister32[[#This Row],[Risk Treatment Safeguard Risk Score]]<AcceptableRisk, IF(tblRiskRegister32[[#This Row],[Risk Treatment Safeguard Risk Score]]<=tblRiskRegister32[[#This Row],[Risk Score]],"Yes","No"),"No"),"Yes") -> No | AH17: =SUMIF(tblRiskRegister32[[#All],[Implementation Year]],"="&tblCostImpacts33[[#This Row],[Year]],tblRiskRegister32[[#All],[Risk Treatment Safeguard Cost]]) -> 0 | AI17: 2027 | AJ17: =IF(tblCostImpacts33[[#This Row],[Impact to Financial Objectives]]<='2. Enterprise Parameters'!$F$13,"Yes","No") -> Yes
B18: Applications | D18: 2.4 | E18: Utilize Automated Software Inventory Tools | I18: =IFERROR(VLOOKUP(tblRiskRegister32[[#This Row],[Asset Class]],tblVCDBIndex[],4,FALSE),"") -> 2 | J18: =IFERROR(VLOOKUP(10*tblRiskRegister32[[#This Row],[Safeguard Maturity Score]]+tblRiskRegister32[[#This Row],[VCDB Index]],tblHITIndexWeightTable[],4,FALSE),"") | K18: =VLOOKUP(tblRiskRegister32[[#This Row],[Asset Class]],tblInherentImpacts30[],2,FALSE) -> 3 | L18: =VLOOKUP(tblRiskRegister32[[#This Row],[Asset Class]],tblInherentImpacts30[],3,FALSE) -> 4 | M18: =VLOOKUP(tblRiskRegister32[[#This Row],[Asset Class]],tblInherentImpacts30[],4,FALSE) -> 1 | N18: =VLOOKUP(tblRiskRegister32[[#This Row],[Asset Class]],tblInherentImpacts30[],5,FALSE) -> 4 | O18: =IFERROR(MAX(tblRiskRegister32[[#This Row],[Impact to Mission]:[Impact to Obligations]])*tblRiskRegister32[[#This Row],[Expectancy Score]],"") | P18: =tblRiskRegister32[[#This Row],[Risk Score]] | R18: 2.4 | S18: Utilize Automated Software Inventory Tools | T18: Utilize software inventory tools, when possible, throughout the enterprise to automate the discovery and documentation of installed software. | W18: =IFERROR(VLOOKUP(10*tblRiskRegister32[[#This Row],[Risk Treatment Safeguard Maturity Score]]+tblRiskRegister32[[#This Row],[VCDB Index]],tblHITIndexWeightTable[],4,FALSE),"") | X18: =VLOOKUP(tblRiskRegister32[[#This Row],[Asset Class]],tblInherentImpacts30[],2,FALSE) -> 3 | Y18: =VLOOKUP(tblRiskRegister32[[#This Row],[Asset Class]],tblInherentImpacts30[],3,FALSE) -> 4 | Z18: =VLOOKUP(tblRiskRegister32[[#This Row],[Asset Class]],tblInherentImpacts30[],3,FALSE) -> 4 | AA18: =VLOOKUP(tblRiskRegister32[[#This Row],[Asset Class]],tblInherentImpacts30[],4,FALSE) -> 1 | AB18: =IFERROR(MAX(tblRiskRegister32[[#This Row],[Risk Treatment Safeguard Impact to Mission]:[Risk Treatment Safeguard Impact to Obligations]])*tblRiskRegister32[[#This Row],[Risk Treatment Safeguard Expectancy Score]],"") | AC18: =IF(tblRiskRegister32[[#This Row],[Risk Score]]>AcceptableRisk,IF(tblRiskRegister32[[#This Row],[Risk Treatment Safeguard Risk Score]]<AcceptableRisk, IF(tblRiskRegister32[[#This Row],[Risk Treatment Safeguard Risk Score]]<=tblRiskRegister32[[#This Row],[Risk Score]],"Yes","No"),"No"),"Yes") -> No | AH18: =SUMIF(tblRiskRegister32[[#All],[Implementation Year]],"="&tblCostImpacts33[[#This Row],[Year]],tblRiskRegister32[[#All],[Risk Treatment Safeguard Cost]]) -> 0 | AI18: 2028 | AJ18: =IF(tblCostImpacts33[[#This Row],[Impact to Financial Objectives]]<='2. Enterprise Parameters'!$F$13,"Yes","No") -> Yes
B19: Applications | D19: 2.5 | E19: Allowlist Authorized Software | I19: =IFERROR(VLOOKUP(tblRiskRegister32[[#This Row],[Asset Class]],tblVCDBIndex[],4,FALSE),"") -> 2 | J19: =IFERROR(VLOOKUP(10*tblRiskRegister32[[#This Row],[Safeguard Maturity Score]]+tblRiskRegister32[[#This Row],[VCDB Index]],tblHITIndexWeightTable[],4,FALSE),"") | K19: =VLOOKUP(tblRiskRegister32[[#This Row],[Asset Class]],tblInherentImpacts30[],2,FALSE) -> 3 | L19: =VLOOKUP(tblRiskRegister32[[#This Row],[Asset Class]],tblInherentImpacts30[],3,FALSE) -> 4 | M19: =VLOOKUP(tblRiskRegister32[[#This Row],[Asset Class]],tblInherentImpacts30[],4,FALSE) -> 1 | N19: =VLOOKUP(tblRiskRegister32[[#This Row],[Asset Class]],tblInherentImpacts30[],5,FALSE) -> 4 | O19: =IFERROR(MAX(tblRiskRegister32[[#This Row],[Impact to Mission]:[Impact to Obligations]])*tblRiskRegister32[[#This Row],[Expectancy Score]],"") | P19: =tblRiskRegister32[[#This Row],[Risk Score]] | R19: 2.5 | S19: Allowlist Authorized Software | T19: Use technical controls, such as application allowlisting, to ensure that only authorized software can execute or be accessed. Reassess bi-annually, or more frequently. | W19: =IFERROR(VLOOKUP(10*tblRiskRegister32[[#This Row],[Risk Treatment Safeguard Maturity Score]]+tblRiskRegister32[[#This Row],[VCDB Index]],tblHITIndexWeightTable[],4,FALSE),"") | X19: =VLOOKUP(tblRiskRegister32[[#This Row],[Asset Class]],tblInherentImpacts30[],2,FALSE) -> 3 | Y19: =VLOOKUP(tblRiskRegister32[[#This Row],[Asset Class]],tblInherentImpacts30[],3,FALSE) -> 4 | Z19: =VLOOKUP(tblRiskRegister32[[#This Row],[Asset Class]],tblInherentImpacts30[],3,FALSE) -> 4 | AA19: =VLOOKUP(tblRiskRegister32[[#This Row],[Asset Class]],tblInherentImpacts30[],4,FALSE) -> 1 | AB19: =IFERROR(MAX(tblRiskRegister32[[#This Row],[Risk Treatment Safeguard Impact to Mission]:[Risk Treatment Safeguard Impact to Obligations]])*tblRiskRegister32[[#This Row],[Risk Treatment Safeguard Expectancy Score]],"") | AC19: =IF(tblRiskRegister32[[#This Row],[Risk Score]]>AcceptableRisk,IF(tblRiskRegister32[[#This Row],[Risk Treatment Safeguard Risk Score]]<AcceptableRisk, IF(tblRiskRegister32[[#This Row],[Risk Treatment Safeguard Risk Score]]<=tblRiskRegister32[[#This Row],[Risk Score]],"Yes","No"),"No"),"Yes") -> No | AH19: =SUMIF(tblRiskRegister32[[#All],[Implementation Year]],"="&tblCostImpacts33[[#This Row],[Year]],tblRiskRegister32[[#All],[Risk Treatment Safeguard Cost]]) -> 0 | AI19: 2029 | AJ19: =IF(tblCostImpacts33[[#This Row],[Impact to Financial Objectives]]<='2. Enterprise Parameters'!$F$13,"Yes","No") -> Yes
B20: Applications | D20: 2.6 | E20: Allowlist Authorized Libraries | I20: =IFERROR(VLOOKUP(tblRiskRegister32[[#This Row],[Asset Class]],tblVCDBIndex[],4,FALSE),"") -> 2 | J20: =IFERROR(VLOOKUP(10*tblRiskRegister32[[#This Row],[Safeguard Maturity Score]]+tblRiskRegister32[[#This Row],[VCDB Index]],tblHITIndexWeightTable[],4,FALSE),"") | K20: =VLOOKUP(tblRiskRegister32[[#This Row],[Asset Class]],tblInherentImpacts30[],2,FALSE) -> 3 | L20: =VLOOKUP(tblRiskRegister32[[#This Row],[Asset Class]],tblInherentImpacts30[],3,FALSE) -> 4 | M20: =VLOOKUP(tblRiskRegister32[[#This Row],[Asset Class]],tblInherentImpacts30[],4,FALSE) -> 1 | N20: =VLOOKUP(tblRiskRegister32[[#This Row],[Asset Class]],tblInherentImpacts30[],5,FALSE) -> 4 | O20: =IFERROR(MAX(tblRiskRegister32[[#This Row],[Impact to Mission]:[Impact to Obligations]])*tblRiskRegister32[[#This Row],[Expectancy Score]],"") | P20: =tblRiskRegister32[[#This Row],[Risk Score]] | R20: 2.6 | S20: Allowlist Authorized Libraries | T20: Use technical controls to ensure that only authorized software libraries, such as specific .dll, .ocx, .so, etc., files, are allowed to load into a system process. Block unauthorized libraries from loading into a system process. Reassess bi-annually, or more frequently. | W20: =IFERROR(VLOOKUP(10*tblRiskRegister32[[#This Row],[Risk Treatment Safeguard Maturity Score]]+tblRiskRegister32[[#This Row],[VCDB Index]],tblHITIndexWeightTable[],4,FALSE),"") | X20: =VLOOKUP(tblRiskRegister32[[#This Row],[Asset Class]],tblInherentImpacts30[],2,FALSE) -> 3 | Y20: =VLOOKUP(tblRiskRegister32[[#This Row],[Asset Class]],tblInherentImpacts30[],3,FALSE) -> 4 | Z20: =VLOOKUP(tblRiskRegister32[[#This Row],[Asset Class]],tblInherentImpacts30[],3,FALSE) -> 4 | AA20: =VLOOKUP(tblRiskRegister32[[#This Row],[Asset Class]],tblInherentImpacts30[],4,FALSE) -> 1 | AB20: =IFERROR(MAX(tblRiskRegister32[[#This Row],[Risk Treatment Safeguard Impact to Mission]:[Risk Treatment Safeguard Impact to Obligations]])*tblRiskRegister32[[#This Row],[Risk Treatment Safeguard Expectancy Score]],"") | AC20: =IF(tblRiskRegister32[[#This Row],[Risk Score]]>AcceptableRisk,IF(tblRiskRegister32[[#This Row],[Risk Treatment Safeguard Risk Score]]<AcceptableRisk, IF(tblRiskRegister32[[#This Row],[Risk Treatment Safeguard Risk Score]]<=tblRiskRegister32[[#This Row],[Risk Score]],"Yes","No"),"No"),"Yes") -> No | AH20: =SUMIF(tblRiskRegister32[[#All],[Implementation Year]],"="&tblCostImpacts33[[#This Row],[Year]],tblRiskRegister32[[#All],[Risk Treatment Safeguard Cost]]) -> 0 | AI20: 2030 | AJ20: =IF(tblCostImpacts33[[#This Row],[Impact to Financial Objectives]]<='2. Enterprise Parameters'!$F$13,"Yes","No") -> Yes
B21: Data | D21: 3.1 | E21: Establish and Maintain a Data Management Process | I21: =IFERROR(VLOOKUP(tblRiskRegister32[[#This Row],[Asset Class]],tblVCDBIndex[],4,FALSE),"") -> 3 | J21: =IFERROR(VLOOKUP(10*tblRiskRegister32[[#This Row],[Safeguard Maturity Score]]+tblRiskRegister32[[#This Row],[VCDB Index]],tblHITIndexWeightTable[],4,FALSE),"") | K21: =VLOOKUP(tblRiskRegister32[[#This Row],[Asset Class]],tblInherentImpacts30[],2,FALSE) -> 4 | L21: =VLOOKUP(tblRiskRegister32[[#This Row],[Asset Class]],tblInherentImpacts30[],3,FALSE) -> 4 | M21: =VLOOKUP(tblRiskRegister32[[#This Row],[Asset Class]],tblInherentImpacts30[],4,FALSE) -> 1 | N21: =VLOOKUP(tblRiskRegister32[[#This Row],[Asset Class]],tblInherentImpacts30[],5,FALSE) -> 4 | O21: =IFERROR(MAX(tblRiskRegister32[[#This Row],[Impact to Mission]:[Impact to Obligations]])*tblRiskRegister32[[#This Row],[Expectancy Score]],"") | P21: =tblRiskRegister32[[#This Row],[Risk Score]] | R21: 3.1 | S21: Establish and Maintain a Data Management Process | T21: Establish and maintain a data management process. In the process, address data sensitivity, data owner, handling of data, data retention limits, and disposal requirements, based on sensitivity and retention standards for the enterprise. Review and update documentation annually, or when significant enterprise changes occur that could impact this Safeguard. | W21: =IFERROR(VLOOKUP(10*tblRiskRegister32[[#This Row],[Risk Treatment Safeguard Maturity Score]]+tblRiskRegister32[[#This Row],[VCDB Index]],tblHITIndexWeightTable[],4,FALSE),"") | X21: =VLOOKUP(tblRiskRegister32[[#This Row],[Asset Class]],tblInherentImpacts30[],2,FALSE) -> 4 | Y21: =VLOOKUP(tblRiskRegister32[[#This Row],[Asset Class]],tblInherentImpacts30[],3,FALSE) -> 4 | Z21: =VLOOKUP(tblRiskRegister32[[#This Row],[Asset Class]],tblInherentImpacts30[],3,FALSE) -> 4 | AA21: =VLOOKUP(tblRiskRegister32[[#This Row],[Asset Class]],tblInherentImpacts30[],4,FALSE) -> 1 | AB21: =IFERROR(MAX(tblRiskRegister32[[#This Row],[Risk Treatment Safeguard Impact to Mission]:[Risk Treatment Safeguard Impact to Obligations]])*tblRiskRegister32[[#This Row],[Risk Treatment Safeguard Expectancy Score]],"") | AC21: =IF(tblRiskRegister32[[#This Row],[Risk Score]]>AcceptableRisk,IF(tblRiskRegister32[[#This Row],[Risk Treatment Safeguard Risk Score]]<AcceptableRisk, IF(tblRiskRegister32[[#This Row],[Risk Treatment Safeguard Risk Score]]<=tblRiskRegister32[[#This Row],[Risk Score]],"Yes","No"),"No"),"Yes") -> No
B22: Data | D22: 3.1 | E22: Encrypt Sensitive Data in Transit | I22: =IFERROR(VLOOKUP(tblRiskRegister32[[#This Row],[Asset Class]],tblVCDBIndex[],4,FALSE),"") -> 3 | J22: =IFERROR(VLOOKUP(10*tblRiskRegister32[[#This Row],[Safeguard Maturity Score]]+tblRiskRegister32[[#This Row],[VCDB Index]],tblHITIndexWeightTable[],4,FALSE),"") | K22: =VLOOKUP(tblRiskRegister32[[#This Row],[Asset Class]],tblInherentImpacts30[],2,FALSE) -> 4 | L22: =VLOOKUP(tblRiskRegister32[[#This Row],[Asset Class]],tblInherentImpacts30[],3,FALSE) -> 4 | M22: =VLOOKUP(tblRiskRegister32[[#This Row],[Asset Class]],tblInherentImpacts30[],4,FALSE) -> 1 | N22: =VLOOKUP(tblRiskRegister32[[#This Row],[Asset Class]],tblInherentImpacts30[],5,FALSE) -> 4 | O22: =IFERROR(MAX(tblRiskRegister32[[#This Row],[Impact to Mission]:[Impact to Obligations]])*tblRiskRegister32[[#This Row],[Expectancy Score]],"") | P22: =tblRiskRegister32[[#This Row],[Risk Score]] | R22: 3.1 | S22: Encrypt Sensitive Data in Transit | T22: Encrypt sensitive data in transit. Example implementations can include: Transport Layer Security (TLS) and Open Secure Shell (OpenSSH). | W22: =IFERROR(VLOOKUP(10*tblRiskRegister32[[#This Row],[Risk Treatment Safeguard Maturity Score]]+tblRiskRegister32[[#This Row],[VCDB Index]],tblHITIndexWeightTable[],4,FALSE),"") | X22: =VLOOKUP(tblRiskRegister32[[#This Row],[Asset Class]],tblInherentImpacts30[],2,FALSE) -> 4 | Y22: =VLOOKUP(tblRiskRegister32[[#This Row],[Asset Class]],tblInherentImpacts30[],3,FALSE) -> 4 | Z22: =VLOOKUP(tblRiskRegister32[[#This Row],[Asset Class]],tblInherentImpacts30[],3,FALSE) -> 4 | AA22: =VLOOKUP(tblRiskRegister32[[#This Row],[Asset Class]],tblInherentImpacts30[],4,FALSE) -> 1 | AB22: =IFERROR(MAX(tblRiskRegister32[[#This Row],[Risk Treatment Safeguard Impact to Mission]:[Risk Treatment Safeguard Impact to Obligations]])*tblRiskRegister32[[#This Row],[Risk Treatment Safeguard Expectancy Score]],"") | AC22: =IF(tblRiskRegister32[[#This Row],[Risk Score]]>AcceptableRisk,IF(tblRiskRegister32[[#This Row],[Risk Treatment Safeguard Risk Score]]<AcceptableRisk, IF(tblRiskRegister32[[#This Row],[Risk Treatment Safeguard Risk Score]]<=tblRiskRegister32[[#This Row],[Risk Score]],"Yes","No"),"No"),"Yes") -> No
B23: Data | C23: MIS 595 Focus | D23: 3.11 | E23: Encrypt Sensitive Data at Rest | F23: Sensitive data stored on bank systems is encrypted using industry-standard AES protocols based on Fabella’s Data Protection Policy. | G23: No Vulnerability | H23: 4 | I23: =IFERROR(VLOOKUP(tblRiskRegister32[[#This Row],[Asset Class]],tblVCDBIndex[],4,FALSE),"") -> 3 | J23: =IFERROR(VLOOKUP(10*tblRiskRegister32[[#This Row],[Safeguard Maturity Score]]+tblRiskRegister32[[#This Row],[VCDB Index]],tblHITIndexWeightTable[],4,FALSE),"") -> 2 | K23: =VLOOKUP(tblRiskRegister32[[#This Row],[Asset Class]],tblInherentImpacts30[],2,FALSE) -> 4 | L23: =VLOOKUP(tblRiskRegister32[[#This Row],[Asset Class]],tblInherentImpacts30[],3,FALSE) -> 4 | M23: =VLOOKUP(tblRiskRegister32[[#This Row],[Asset Class]],tblInherentImpacts30[],4,FALSE) -> 1 | N23: =VLOOKUP(tblRiskRegister32[[#This Row],[Asset Class]],tblInherentImpacts30[],5,FALSE) -> 4 | O23: =IFERROR(MAX(tblRiskRegister32[[#This Row],[Impact to Mission]:[Impact to Obligations]])*tblRiskRegister32[[#This Row],[Expectancy Score]],"") -> 8 | P23: =tblRiskRegister32[[#This Row],[Risk Score]] -> 8 | Q23: Accept | R23: 3.11 | S23: Encrypt Sensitive Data at Rest | T23: Encrypt sensitive data at rest on servers, applications, and databases containing sensitive data. Storage-layer encryption, also known as server-side encryption, meets the minimum requirement of this Safeguard. Additional encryption methods may include application-layer encryption, also known as client-side encryption, where access to the data storage device(s) does not permit access to the plain-text data. | W23: =IFERROR(VLOOKUP(10*tblRiskRegister32[[#This Row],[Risk Treatment Safeguard Maturity Score]]+tblRiskRegister32[[#This Row],[VCDB Index]],tblHITIndexWeightTable[],4,FALSE),"") | X23: =VLOOKUP(tblRiskRegister32[[#This Row],[Asset Class]],tblInherentImpacts30[],2,FALSE) -> 4 | Y23: =VLOOKUP(tblRiskRegister32[[#This Row],[Asset Class]],tblInherentImpacts30[],3,FALSE) -> 4 | Z23: =VLOOKUP(tblRiskRegister32[[#This Row],[Asset Class]],tblInherentImpacts30[],3,FALSE) -> 4 | AA23: =VLOOKUP(tblRiskRegister32[[#This Row],[Asset Class]],tblInherentImpacts30[],4,FALSE) -> 1 | AB23: =IFERROR(MAX(tblRiskRegister32[[#This Row],[Risk Treatment Safeguard Impact to Mission]:[Risk Treatment Safeguard Impact to Obligations]])*tblRiskRegister32[[#This Row],[Risk Treatment Safeguard Expectancy Score]],"") | AC23: =IF(tblRiskRegister32[[#This Row],[Risk Score]]>AcceptableRisk,IF(tblRiskRegister32[[#This Row],[Risk Treatment Safeguard Risk Score]]<AcceptableRisk, IF(tblRiskRegister32[[#This Row],[Risk Treatment Safeguard Risk Score]]<=tblRiskRegister32[[#This Row],[Risk Score]],"Yes","No"),"No"),"Yes") -> Yes
B24: Network | D24: 3.12 | E24: Segment Data Processing and Storage Based on Sensitivity | I24: =IFERROR(VLOOKUP(tblRiskRegister32[[#This Row],[Asset Class]],tblVCDBIndex[],4,FALSE),"") -> 1 | J24: =IFERROR(VLOOKUP(10*tblRiskRegister32[[#This Row],[Safeguard Maturity Score]]+tblRiskRegister32[[#This Row],[VCDB Index]],tblHITIndexWeightTable[],4,FALSE),"") | K24: =VLOOKUP(tblRiskRegister32[[#This Row],[Asset Class]],tblInherentImpacts30[],2,FALSE) -> 4 | L24: =VLOOKUP(tblRiskRegister32[[#This Row],[Asset Class]],tblInherentImpacts30[],3,FALSE) -> 5 | M24: =VLOOKUP(tblRiskRegister32[[#This Row],[Asset Class]],tblInherentImpacts30[],4,FALSE) -> 1 | N24: =VLOOKUP(tblRiskRegister32[[#This Row],[Asset Class]],tblInherentImpacts30[],5,FALSE) -> 5 | O24: =IFERROR(MAX(tblRiskRegister32[[#This Row],[Impact to Mission]:[Impact to Obligations]])*tblRiskRegister32[[#This Row],[Expectancy Score]],"") | P24: =tblRiskRegister32[[#This Row],[Risk Score]] | R24: 3.12 | S24: Segment Data Processing and Storage Based on Sensitivity | T24: Segment data processing and storage based on the sensitivity of the data. Do not process sensitive data on enterprise assets intended for lower sensitivity data. | W24: =IFERROR(VLOOKUP(10*tblRiskRegister32[[#This Row],[Risk Treatment Safeguard Maturity Score]]+tblRiskRegister32[[#This Row],[VCDB Index]],tblHITIndexWeightTable[],4,FALSE),"") | X24: =VLOOKUP(tblRiskRegister32[[#This Row],[Asset Class]],tblInherentImpacts30[],2,FALSE) -> 4 | Y24: =VLOOKUP(tblRiskRegister32[[#This Row],[Asset Class]],tblInherentImpacts30[],3,FALSE) -> 5 | Z24: =VLOOKUP(tblRiskRegister32[[#This Row],[Asset Class]],tblInherentImpacts30[],3,FALSE) -> 5 | AA24: =VLOOKUP(tblRiskRegister32[[#This Row],[Asset Class]],tblInherentImpacts30[],4,FALSE) -> 1 | AB24: =IFERROR(MAX(tblRiskRegister32[[#This Row],[Risk Treatment Safeguard Impact to Mission]:[Risk Treatment Safeguard Impact to Obligations]])*tblRiskRegister32[[#This Row],[Risk Treatment Safeguard Expectancy Score]],"") | AC24: =IF(tblRiskRegister32[[#This Row],[Risk Score]]>AcceptableRisk,IF(tblRiskRegister32[[#This Row],[Risk Treatment Safeguard Risk Score]]<AcceptableRisk, IF(tblRiskRegister32[[#This Row],[Risk Treatment Safeguard Risk Score]]<=tblRiskRegister32[[#This Row],[Risk Score]],"Yes","No"),"No"),"Yes") -> No
B25: Data | D25: 3.2 | E25: Establish and Maintain a Data Inventory | I25: =IFERROR(VLOOKUP(tblRiskRegister32[[#This Row],[Asset Class]],tblVCDBIndex[],4,FALSE),"") -> 3 | J25: =IFERROR(VLOOKUP(10*tblRiskRegister32[[#This Row],[Safeguard Maturity Score]]+tblRiskRegister32[[#This Row],[VCDB Index]],tblHITIndexWeightTable[],4,FALSE),"") | K25: =VLOOKUP(tblRiskRegister32[[#This Row],[Asset Class]],tblInherentImpacts30[],2,FALSE) -> 4 | L25: =VLOOKUP(tblRiskRegister32[[#This Row],[Asset Class]],tblInherentImpacts30[],3,FALSE) -> 4 | M25: =VLOOKUP(tblRiskRegister32[[#This Row],[Asset Class]],tblInherentImpacts30[],4,FALSE) -> 1 | N25: =VLOOKUP(tblRiskRegister32[[#This Row],[Asset Class]],tblInherentImpacts30[],5,FALSE) -> 4 | O25: =IFERROR(MAX(tblRiskRegister32[[#This Row],[Impact to Mission]:[Impact to Obligations]])*tblRiskRegister32[[#This Row],[Expectancy Score]],"") | P25: =tblRiskRegister32[[#This Row],[Risk Score]] | R25: 3.2 | S25: Establish and Maintain a Data Inventory | T25: Establish and maintain a data inventory, based on the enterprise’s data management process. Inventory sensitive data, at a minimum. Review and update inventory annually, at a minimum, with a priority on sensitive data. | W25: =IFERROR(VLOOKUP(10*tblRiskRegister32[[#This Row],[Risk Treatment Safeguard Maturity Score]]+tblRiskRegister32[[#This Row],[VCDB Index]],tblHITIndexWeightTable[],4,FALSE),"") | X25: =VLOOKUP(tblRiskRegister32[[#This Row],[Asset Class]],tblInherentImpacts30[],2,FALSE) -> 4 | Y25: =VLOOKUP(tblRiskRegister32[[#This Row],[Asset Class]],tblInherentImpacts30[],3,FALSE) -> 4 | Z25: =VLOOKUP(tblRiskRegister32[[#This Row],[Asset Class]],tblInherentImpacts30[],3,FALSE) -> 4 | AA25: =VLOOKUP(tblRiskRegister32[[#This Row],[Asset Class]],tblInherentImpacts30[],4,FALSE) -> 1 | AB25: =IFERROR(MAX(tblRiskRegister32[[#This Row],[Risk Treatment Safeguard Impact to Mission]:[Risk Treatment Safeguard Impact to Obligations]])*tblRiskRegister32[[#This Row],[Risk Treatment Safeguard Expectancy Score]],"") | AC25: =IF(tblRiskRegister32[[#This Row],[Risk Score]]>AcceptableRisk,IF(tblRiskRegister32[[#This Row],[Risk Treatment Safeguard Risk Score]]<AcceptableRisk, IF(tblRiskRegister32[[#This Row],[Risk Treatment Safeguard Risk Score]]<=tblRiskRegister32[[#This Row],[Risk Score]],"Yes","No"),"No"),"Yes") -> No
B26: Data | D26: 3.3 | E26: Configure Data Access Control Lists | I26: =IFERROR(VLOOKUP(tblRiskRegister32[[#This Row],[Asset Class]],tblVCDBIndex[],4,FALSE),"") -> 3 | J26: =IFERROR(VLOOKUP(10*tblRiskRegister32[[#This Row],[Safeguard Maturity Score]]+tblRiskRegister32[[#This Row],[VCDB Index]],tblHITIndexWeightTable[],4,FALSE),"") | K26: =VLOOKUP(tblRiskRegister32[[#This Row],[Asset Class]],tblInherentImpacts30[],2,FALSE) -> 4 | L26: =VLOOKUP(tblRiskRegister32[[#This Row],[Asset Class]],tblInherentImpacts30[],3,FALSE) -> 4 | M26: =VLOOKUP(tblRiskRegister32[[#This Row],[Asset Class]],tblInherentImpacts30[],4,FALSE) -> 1 | N26: =VLOOKUP(tblRiskRegister32[[#This Row],[Asset Class]],tblInherentImpacts30[],5,FALSE) -> 4 | O26: =IFERROR(MAX(tblRiskRegister32[[#This Row],[Impact to Mission]:[Impact to Obligations]])*tblRiskRegister32[[#This Row],[Expectancy Score]],"") | P26: =tblRiskRegister32[[#This Row],[Risk Score]] | R26: 3.3 | S26: Configure Data Access Control Lists | T26: Configure data access control lists based on a user’s need to know. Apply data access control lists, also known as access permissions, to local and remote file systems, databases, and applications. | W26: =IFERROR(VLOOKUP(10*tblRiskRegister32[[#This Row],[Risk Treatment Safeguard Maturity Score]]+tblRiskRegister32[[#This Row],[VCDB Index]],tblHITIndexWeightTable[],4,FALSE),"") | X26: =VLOOKUP(tblRiskRegister32[[#This Row],[Asset Class]],tblInherentImpacts30[],2,FALSE) -> 4 | Y26: =VLOOKUP(tblRiskRegister32[[#This Row],[Asset Class]],tblInherentImpacts30[],3,FALSE) -> 4 | Z26: =VLOOKUP(tblRiskRegister32[[#This Row],[Asset Class]],tblInherentImpacts30[],3,FALSE) -> 4 | AA26: =VLOOKUP(tblRiskRegister32[[#This Row],[Asset Class]],tblInherentImpacts30[],4,FALSE) -> 1 | AB26: =IFERROR(MAX(tblRiskRegister32[[#This Row],[Risk Treatment Safeguard Impact to Mission]:[Risk Treatment Safeguard Impact to Obligations]])*tblRiskRegister32[[#This Row],[Risk Treatment Safeguard Expectancy Score]],"") | AC26: =IF(tblRiskRegister32[[#This Row],[Risk Score]]>AcceptableRisk,IF(tblRiskRegister32[[#This Row],[Risk Treatment Safeguard Risk Score]]<AcceptableRisk, IF(tblRiskRegister32[[#This Row],[Risk Treatment Safeguard Risk Score]]<=tblRiskRegister32[[#This Row],[Risk Score]],"Yes","No"),"No"),"Yes") -> No
